<mujoco model="firefighter">
  <compiler angle="radian"/>
  <asset>
    <material name="white" rgba="1 1 1 1"/>
    <material name="silver" rgba=".753 .753 .753 1"/>

    <mesh name="G_base" file="assets/mycobot_280_pi/assets/collision/G_base.stl"/>
    <mesh name="joint1" file="assets/mycobot_280_pi/assets/collision/joint1.stl"/>
    <mesh name="joint2" file="assets/mycobot_280_pi/assets/collision/joint2.stl"/>
    <mesh name="joint3" file="assets/mycobot_280_pi/assets/collision/joint3.stl"/>
    <mesh name="joint4" file="assets/mycobot_280_pi/assets/collision/joint4.stl"/>
    <mesh name="joint5" file="assets/mycobot_280_pi/assets/collision/joint5.stl"/>
    <mesh name="joint6" file="assets/mycobot_280_pi/assets/collision/joint6.stl"/>
    <mesh name="joint7" file="assets/mycobot_280_pi/assets/collision/joint7.stl"/>
  </asset>
  <worldbody>
    <body name="link_base" pos="0 0 0">
      <geom pos="0 0 -0.03" quat="0.707105 0 0 0.707108" type="mesh" contype="0" conaffinity="0" group="1" density="0" mesh="G_base"/>
      <geom pos="0 0 -0.03" quat="0.707105 0 0 0.707108" type="mesh" mesh="G_base"/>
      <geom type="mesh" contype="0" conaffinity="0" group="1" density="0" mesh="joint1"/>
      <geom type="mesh" mesh="joint1"/>
      <body name="joint2" pos="0 0 0.13956">
        <joint name="joint2_to_joint1" pos="0 0 0" axis="0 0 1" range="-3.14 3.14159" actuatorfrcrange="-1000 1000"/>
        <geom pos="0 0 -0.06096" quat="0.707105 0 0 -0.707108" type="mesh" contype="0" conaffinity="0" group="1" density="0" mesh="joint2"/>
        <geom pos="0 0 -0.06096" quat="0.707105 0 0 -0.707108" type="mesh" mesh="joint2"/>
        <body name="joint3" pos="0 0 -0.001" quat="0.499998 0.500002 0.5 -0.5">
          <joint name="joint3_to_joint2" pos="0 0 0" axis="0 0 1" range="-3.14 3.14159" actuatorfrcrange="-1000 1000"/>
          <geom pos="0 0 0.03256" quat="0.707105 0 -0.707108 0" type="mesh" contype="0" conaffinity="0" group="1" density="0" mesh="joint3"/>
          <geom pos="0 0 0.03256" quat="0.707105 0 -0.707108 0" type="mesh" mesh="joint3"/>
          <body name="joint4" pos="-0.1104 0 0">
            <joint name="joint4_to_joint3" pos="0 0 0" axis="0 0 1" range="-3.14 3.14159" actuatorfrcrange="-1000 1000"/>
            <geom pos="0 0 0.03056" quat="0.707105 0 -0.707108 0" type="mesh" contype="0" conaffinity="0" group="1" density="0" mesh="joint4"/>
            <geom pos="0 0 0.03056" quat="0.707105 0 -0.707108 0" type="mesh" mesh="joint4"/>
            <body name="joint5" pos="-0.096 0 0.06462" quat="0.707105 0 0 -0.707108">
              <joint name="joint5_to_joint4" pos="0 0 0" axis="0 0 1" range="-3.14 3.14159" actuatorfrcrange="-1000 1000"/>
              <geom pos="0 0 -0.03356" quat="0.499998 0.500002 -0.5 0.5" type="mesh" contype="0" conaffinity="0" group="1" density="0" mesh="joint5"/>
              <geom pos="0 0 -0.03356" quat="0.499998 0.500002 -0.5 0.5" type="mesh" mesh="joint5"/>
              <body name="joint6" pos="0 -0.07318 0" quat="0.499998 0.5 -0.5 0.500002">
                <joint name="joint6_to_joint5" pos="0 0 0" axis="0 0 1" range="-3.14 3.14159" actuatorfrcrange="-1000 1000"/>
                <geom pos="0 0 -0.038" type="mesh" contype="0" conaffinity="0" group="1" density="0" mesh="joint6"/>
                <geom pos="0 0 -0.038" type="mesh" mesh="joint6"/>
                <body name="joint6_flange" pos="0 0.0456 0" quat="0.707105 -0.707108 0 0">
                  <joint name="joint6output_to_joint6" pos="0 0 0" axis="0 0 1" range="-3.14 3.14159" actuatorfrcrange="-1000 1000"/>
                  <geom pos="0 0 -0.012" type="mesh" contype="0" conaffinity="0" group="1" density="0" mesh="joint7"/>
                  <geom pos="0 0 -0.012" type="mesh" mesh="joint7"/>
                </body>
              </body>
            </body>
          </body>
        </body>
      </body>
    </body>
  </worldbody>

  <actuator>
    <general joint="joint2_to_joint1" ctrllimited="true" ctrlrange="-3.14 3.14" /> 
    <general joint="joint3_to_joint2" ctrllimited="true" ctrlrange="-3.14 3.14" />
    <general joint="joint4_to_joint3" ctrllimited="true" ctrlrange="-3.14 3.14" />
    <general joint="joint5_to_joint4" ctrllimited="true" ctrlrange="-3.14 3.14" />
    <general joint="joint6_to_joint5" ctrllimited="true" ctrlrange="-3.14 3.14" />
    <general joint="joint6output_to_joint6" ctrllimited="true" ctrlrange="-3.14 3.14" />

    <!-- <position name="gripper_lite_left" joint="gripper_lite_left_joint" ctrllimited="true" ctrlrange="0 0.02" kp="12"/> 
    <position name="gripper_lite_right" joint="gripper_lite_right_joint" ctrllimited="true" ctrlrange="-0.02 0" kp="12"/>  -->
  </actuator>

</mujoco>
